
camundaWorkingCheck.py::test_CamundaTest[785c37f04150dd1c7281c2dbc661d316qweDelimqwe1649170639qweDelimqweroot-0] 
-------------------------------- live log call ---------------------------------
INFO     root:camundaWorkingCheck.py:16 Try connect to camunda
FAILED

=================================== FAILURES ===================================
_ test_CamundaTest[785c37f04150dd1c7281c2dbc661d316qweDelimqwe1649170639qweDelimqweroot-0] _

seal = '785c37f04150dd1c7281c2dbc661d316qweDelimqwe1649170639qweDelimqweroot'
debugLevel = '0'

    @allure.title('Seal update test')
    def test_CamundaTest(seal, debugLevel):
        debugEnable(int(debugLevel))
        seal1 = seal.replace("qweDelimqwe", "|")
>       camundaTest(seal1)

camundaWorkingCheck.py:25: 
_ _ _ _ _ _ _ _ _ _ _ _ _ _ _ _ _ _ _ _ _ _ _ _ _ _ _ _ _ _ _ _ _ _ _ _ _ _ _ _ 

seal = '785c37f04150dd1c7281c2dbc661d316|1649170639|root'

    @allure.step('Try to connect')
    def camundaTest(seal):
        host = getFromConfig("host")
        login = getFromConfig("login")
        logging.info("Try connect to camunda")
        camundaTestRequest = requests.get(f"http://{host}/api/bpm/camunda/engine?login={login}&seal={seal}")
>       assert '[{"name": "default"}]' in camundaTestRequest.text, "Camunda not work"
E       AssertionError: Camunda not work
E       assert '[{"name": "default"}]' in '{"data": null, "error": {"code": 500, "message": "An unexpected error has occurred: HTTPConnectionPool(host=\'localhost\', port=8080): Max retries exceeded with url: /engine-rest/engine?login=root&seal=785c37f04150dd1c7281c2dbc661d316%7C1649170639%7Croot (Caused by NewConnectionError(\'<urllib3.connection.HTTPConnection object at 0x7f38203a0898>: Failed to establish a new connection: [Errno 111] Connection refused\',))"}}'
E        +  where '{"data": null, "error": {"code": 500, "message": "An unexpected error has occurred: HTTPConnectionPool(host=\'localhost\', port=8080): Max retries exceeded with url: /engine-rest/engine?login=root&seal=785c37f04150dd1c7281c2dbc661d316%7C1649170639%7Croot (Caused by NewConnectionError(\'<urllib3.connection.HTTPConnection object at 0x7f38203a0898>: Failed to establish a new connection: [Errno 111] Connection refused\',))"}}' = <Response [500]>.text

camundaWorkingCheck.py:18: AssertionError
------------------------------ Captured log call -------------------------------
INFO     root:camundaWorkingCheck.py:16 Try connect to camunda
=========================== short test summary info ============================
FAILED camundaWorkingCheck.py::test_CamundaTest[785c37f04150dd1c7281c2dbc661d316qweDelimqwe1649170639qweDelimqweroot-0]
============================== 1 failed in 1.60s ===============================
